# 错误和异常

---

## 什么是异常

在编写程序的时候，错误是难免的，入语法错误、逻辑错误等。当`Python`检测到一个错误的解释器就无法执行下去，于是抛出响应信息，这些可以笼统的称为异常信息。即便`Python`程序的语法正确，在运行的时候也有可能发生错误。运行期检测到的错误称为异常。异常处理的意义：当程序运行的时候出现异常，会导致程序终止运行，为了避免这种情况，需要预先对可能出现的异常进行处理，这样一旦出现该异常，就可以使用另一种方式解决问题，不会导致程序终止。

![异常处理](D:\repository\PythonNotes\notes\第3章 Python语法\images\异常处理.png)

## 异常类型

`NameError IndexError keyError EOFError FileNotFoundError ValueError ModuleNotFoundError...`

1. 当你要处理的内容不确定的时候最容易出错：
   1. 有用户参与
   2. 外界数据接入
   3. 从文件中或网上读取

2. 当有多行报错的时候是为什么？

   在嵌套调用的过程中，内部的代码出了问题，外部所有的调用的地方都成为报错追溯信息的一部分

   **怎么解决**：首先找你写的代码，出错的哪一行，看看能不能看出问题，如果不行就百度

## 异常处理过程

1. 单分支：异常处理必须与实际报错一致
2. 多分支：从上到下报错的代码只要找到一个和报错类型相符的分支就执行分支代码，然后退出分支。如果找不到，会一直往下走，最后还是没有找到会报错

![异常处理过程](D:\repository\PythonNotes\notes\第3章 Python语法\images\异常处理过程.png)

```python
l = ['login','register']
for num,i in enumrate(l,1):
    print(num,i)
try:
    num = int(input('num >>>'))
    print(l[num-1])
except (ValueError,IndexError):  # 异常处理必须与实际报错一致，多分支合并
    print('您的输入不合法')
```

3. 万能异常

   - 所有程序开发完用
   - `try:...except Exception as e: print(e)`打印出错误信息
   - `try:...except:`
   - `try:...except(...):...except Exception as e:`
     - 多分支加万能异常
     - 万能异常放最后
4. `else`分支

```python
try:
    print('aaa')
    name
    [][1]
except NameError:
    print('name error')
except IndexError:
    print('index error')
else:  # 当try中的代码不发生异常时，执行else
    print('else')
```

5. `finally`分支
   1. 即使遇到报错，程序结束，也会先执行`finally`中代码，然后再执行程序
   2. 用来回收一些操作系统的资源：数据库连接，打开的文件句柄，网络连接
   3. `try...except`  `try...except...else`   `try...finally`   `try...except...finally`
   4. `try...except...else...finally`

```python
try:
    print('aaa')
    name
    [][1]
except NameError:
    print('name error')
except IndexError:
    print('index error')
else:  # 当try中的代码不发生异常时，执行else
    print('else')
finally:  # 无论如何都会被执行
    print('finally')
```

## 主动抛出异常

`raise ValueError('你写的不对')`

```python
# 打印异常信息,
# traceback模块精确模仿Python解释器stack trace行为。应尽量使用这个模块，可以在控制台更直观的显示异常
import traceback
try:
    print(1/0)
except:
    traceback.print_exc()
```

